[Thu Jul 16 03:10:41 2015] 'qwdqwdqfjoqwifjqoijvoqijwqoijvoqivwjqooiqwj.com' raised:
Traceback (most recent call last):
  File "/root/droopescan/dscan/plugins/internal/scan.py", line 134, in _process_identify_futures
    cms_name, repaired_url = future.result(timeout=opts['timeout_host'])
  File "/usr/local/lib/python2.7/dist-packages/concurrent/futures/_base.py", line 396, in result
    return self.__get_result()
  File "/usr/local/lib/python2.7/dist-packages/concurrent/futures/thread.py", line 55, in run
    result = self.fn(*self.args, **self.kwargs)
  File "/root/droopescan/dscan/plugins/internal/scan.py", line 152, in _process_cms_identify
    url = self.determine_redirect(url, opts['verb'], opts['timeout'])
  File "/root/droopescan/dscan/plugins/internal/base_plugin_internal.py", line 342, in determine_redirect
    r = requests_verb(url, timeout=timeout)
  File "/usr/lib/python2.7/dist-packages/requests/sessions.py", line 489, in head
    return self.request('HEAD', url, **kwargs)
  File "/usr/lib/python2.7/dist-packages/requests/sessions.py", line 457, in request
    resp = self.send(prep, **send_kwargs)
  File "/usr/lib/python2.7/dist-packages/requests/sessions.py", line 569, in send
    r = adapter.send(request, **kwargs)
  File "/usr/lib/python2.7/dist-packages/requests/adapters.py", line 407, in send
    raise ConnectionError(err, request=request)
ConnectionError: ('Connection aborted.', gaierror(-2, 'Name or service not known'))

