[Tue Aug 18 16:56:37 2015] Line qwidfjqowifqwihfqowhifoqwihfiqwhiofhoiwqhoiwfqhoifwq.com '<class 'requests.exceptions.ConnectionError'>: ('Connection aborted.', gaierror(-2, 'Name or service not known'))'
[Tue Aug 18 16:56:37 2015] Line qwidfjqowifqwihfqowhifoqwihfiqwhiofhoiwqhoiwfqhoifwq.com '<class 'requests.exceptions.ConnectionError'>: ('Connection aborted.', gaierror(-2, 'Name or service not known'))'
[Tue Aug 18 16:56:37 2015] Line example2.com '<class 'requests.exceptions.ConnectionError'>: ('Connection aborted.', gaierror(-2, 'Name or service not known'))'
[Tue Aug 18 20:11:57 2015] Line 'example1.com' raised:
Traceback (most recent call last):
  File "/root/droopescan/dscan/plugins/internal/base_plugin_internal.py", line 356, in _process_results_multisite
    output = result['future'].result(timeout=timeout_host)
  File "/usr/lib/python3.4/concurrent/futures/_base.py", line 402, in result
    return self.__get_result()
  File "/usr/lib/python3.4/concurrent/futures/_base.py", line 354, in __get_result
    raise self._exception
  File "/usr/lib/python3.4/concurrent/futures/thread.py", line 54, in run
    result = self.fn(*self.args, **self.kwargs)
  File "/root/droopescan/dscan/plugins/internal/base_plugin_internal.py", line 402, in url_scan
    url, host_header = self.determine_redirect(url, host_header, opts)
  File "/root/droopescan/dscan/plugins/internal/base_plugin_internal.py", line 485, in determine_redirect
    opts['timeout'], self._generate_headers(host_header))
  File "/root/droopescan/dscan/plugins/internal/base_plugin_internal.py", line 451, in _determine_redirect
    r = requests_verb(url, timeout=timeout, headers=headers, allow_redirects=False)
  File "/usr/lib/python3/dist-packages/requests/sessions.py", line 489, in head
    return self.request('HEAD', url, **kwargs)
  File "/usr/lib/python3/dist-packages/requests/sessions.py", line 457, in request
    resp = self.send(prep, **send_kwargs)
  File "/usr/lib/python3/dist-packages/requests/sessions.py", line 569, in send
    r = adapter.send(request, **kwargs)
  File "/usr/local/lib/python3.4/dist-packages/responses.py", line 283, in unbound_on_send
    return self._on_request(adapter, request, *a, **kwargs)
  File "/usr/local/lib/python3.4/dist-packages/responses.py", line 231, in _on_request
    raise response
requests.exceptions.ConnectionError: Connection refused: HEAD http://example1.com/

[Tue Aug 18 20:11:57 2015] Line 'example2.com' raised:
Traceback (most recent call last):
  File "/root/droopescan/dscan/plugins/internal/base_plugin_internal.py", line 356, in _process_results_multisite
    output = result['future'].result(timeout=timeout_host)
  File "/usr/lib/python3.4/concurrent/futures/_base.py", line 395, in result
    return self.__get_result()
  File "/usr/lib/python3.4/concurrent/futures/_base.py", line 354, in __get_result
    raise self._exception
  File "/usr/lib/python3.4/concurrent/futures/thread.py", line 54, in run
    result = self.fn(*self.args, **self.kwargs)
  File "/root/droopescan/dscan/plugins/internal/base_plugin_internal.py", line 402, in url_scan
    url, host_header = self.determine_redirect(url, host_header, opts)
  File "/root/droopescan/dscan/plugins/internal/base_plugin_internal.py", line 485, in determine_redirect
    opts['timeout'], self._generate_headers(host_header))
  File "/root/droopescan/dscan/plugins/internal/base_plugin_internal.py", line 451, in _determine_redirect
    r = requests_verb(url, timeout=timeout, headers=headers, allow_redirects=False)
  File "/usr/lib/python3/dist-packages/requests/sessions.py", line 489, in head
    return self.request('HEAD', url, **kwargs)
  File "/usr/lib/python3/dist-packages/requests/sessions.py", line 457, in request
    resp = self.send(prep, **send_kwargs)
  File "/usr/lib/python3/dist-packages/requests/sessions.py", line 569, in send
    r = adapter.send(request, **kwargs)
  File "/usr/local/lib/python3.4/dist-packages/responses.py", line 283, in unbound_on_send
    return self._on_request(adapter, request, *a, **kwargs)
  File "/usr/local/lib/python3.4/dist-packages/responses.py", line 231, in _on_request
    raise response
requests.exceptions.ConnectionError: Connection refused: HEAD http://example2.com/

[Tue Aug 18 20:11:57 2015] Line 'example3.com' raised:
Traceback (most recent call last):
  File "/root/droopescan/dscan/plugins/internal/base_plugin_internal.py", line 356, in _process_results_multisite
    output = result['future'].result(timeout=timeout_host)
  File "/usr/lib/python3.4/concurrent/futures/_base.py", line 395, in result
    return self.__get_result()
  File "/usr/lib/python3.4/concurrent/futures/_base.py", line 354, in __get_result
    raise self._exception
  File "/usr/lib/python3.4/concurrent/futures/thread.py", line 54, in run
    result = self.fn(*self.args, **self.kwargs)
  File "/root/droopescan/dscan/plugins/internal/base_plugin_internal.py", line 402, in url_scan
    url, host_header = self.determine_redirect(url, host_header, opts)
  File "/root/droopescan/dscan/plugins/internal/base_plugin_internal.py", line 485, in determine_redirect
    opts['timeout'], self._generate_headers(host_header))
  File "/root/droopescan/dscan/plugins/internal/base_plugin_internal.py", line 451, in _determine_redirect
    r = requests_verb(url, timeout=timeout, headers=headers, allow_redirects=False)
  File "/usr/lib/python3/dist-packages/requests/sessions.py", line 489, in head
    return self.request('HEAD', url, **kwargs)
  File "/usr/lib/python3/dist-packages/requests/sessions.py", line 457, in request
    resp = self.send(prep, **send_kwargs)
  File "/usr/lib/python3/dist-packages/requests/sessions.py", line 569, in send
    r = adapter.send(request, **kwargs)
  File "/usr/local/lib/python3.4/dist-packages/responses.py", line 283, in unbound_on_send
    return self._on_request(adapter, request, *a, **kwargs)
  File "/usr/local/lib/python3.4/dist-packages/responses.py", line 231, in _on_request
    raise response
requests.exceptions.ConnectionError: Connection refused: HEAD http://example3.com/

[Tue Aug 18 20:11:57 2015] Line 'example4.com' raised:
Traceback (most recent call last):
  File "/root/droopescan/dscan/plugins/internal/base_plugin_internal.py", line 356, in _process_results_multisite
    output = result['future'].result(timeout=timeout_host)
  File "/usr/lib/python3.4/concurrent/futures/_base.py", line 395, in result
    return self.__get_result()
  File "/usr/lib/python3.4/concurrent/futures/_base.py", line 354, in __get_result
    raise self._exception
  File "/usr/lib/python3.4/concurrent/futures/thread.py", line 54, in run
    result = self.fn(*self.args, **self.kwargs)
  File "/root/droopescan/dscan/plugins/internal/base_plugin_internal.py", line 402, in url_scan
    url, host_header = self.determine_redirect(url, host_header, opts)
  File "/root/droopescan/dscan/plugins/internal/base_plugin_internal.py", line 485, in determine_redirect
    opts['timeout'], self._generate_headers(host_header))
  File "/root/droopescan/dscan/plugins/internal/base_plugin_internal.py", line 451, in _determine_redirect
    r = requests_verb(url, timeout=timeout, headers=headers, allow_redirects=False)
  File "/usr/lib/python3/dist-packages/requests/sessions.py", line 489, in head
    return self.request('HEAD', url, **kwargs)
  File "/usr/lib/python3/dist-packages/requests/sessions.py", line 457, in request
    resp = self.send(prep, **send_kwargs)
  File "/usr/lib/python3/dist-packages/requests/sessions.py", line 569, in send
    r = adapter.send(request, **kwargs)
  File "/usr/local/lib/python3.4/dist-packages/responses.py", line 283, in unbound_on_send
    return self._on_request(adapter, request, *a, **kwargs)
  File "/usr/local/lib/python3.4/dist-packages/responses.py", line 231, in _on_request
    raise response
requests.exceptions.ConnectionError: Connection refused: HEAD http://example4.com/

[Tue Aug 18 20:18:22 2015] Line 'example1.com' raised:
Traceback (most recent call last):
  File "/root/droopescan/dscan/plugins/internal/base_plugin_internal.py", line 362, in _process_results_multisite
    self.out.result(output, functionality)
  File "/root/droopescan/dscan/common/output.py", line 146, in result
    print(json.dumps(result))
  File "/usr/lib/python3.4/json/__init__.py", line 230, in dumps
    return _default_encoder.encode(obj)
  File "/usr/lib/python3.4/json/encoder.py", line 192, in encode
    chunks = self.iterencode(o, _one_shot=True)
  File "/usr/lib/python3.4/json/encoder.py", line 250, in iterencode
    return _iterencode(o, 0)
  File "/usr/lib/python3.4/json/encoder.py", line 173, in default
    raise TypeError(repr(o) + " is not JSON serializable")
TypeError: <MagicMock name='url_scan()' id='3057904140'> is not JSON serializable

[Tue Aug 18 20:18:22 2015] Line 'example2.com' raised:
Traceback (most recent call last):
  File "/root/droopescan/dscan/plugins/internal/base_plugin_internal.py", line 362, in _process_results_multisite
    self.out.result(output, functionality)
  File "/root/droopescan/dscan/common/output.py", line 146, in result
    print(json.dumps(result))
  File "/usr/lib/python3.4/json/__init__.py", line 230, in dumps
    return _default_encoder.encode(obj)
  File "/usr/lib/python3.4/json/encoder.py", line 192, in encode
    chunks = self.iterencode(o, _one_shot=True)
  File "/usr/lib/python3.4/json/encoder.py", line 250, in iterencode
    return _iterencode(o, 0)
  File "/usr/lib/python3.4/json/encoder.py", line 173, in default
    raise TypeError(repr(o) + " is not JSON serializable")
TypeError: <MagicMock name='url_scan()' id='3057904140'> is not JSON serializable

[Tue Aug 18 20:18:22 2015] Line 'example3.com' raised:
Traceback (most recent call last):
  File "/root/droopescan/dscan/plugins/internal/base_plugin_internal.py", line 362, in _process_results_multisite
    self.out.result(output, functionality)
  File "/root/droopescan/dscan/common/output.py", line 146, in result
    print(json.dumps(result))
  File "/usr/lib/python3.4/json/__init__.py", line 230, in dumps
    return _default_encoder.encode(obj)
  File "/usr/lib/python3.4/json/encoder.py", line 192, in encode
    chunks = self.iterencode(o, _one_shot=True)
  File "/usr/lib/python3.4/json/encoder.py", line 250, in iterencode
    return _iterencode(o, 0)
  File "/usr/lib/python3.4/json/encoder.py", line 173, in default
    raise TypeError(repr(o) + " is not JSON serializable")
TypeError: <MagicMock name='url_scan()' id='3057904140'> is not JSON serializable

[Tue Aug 18 20:18:22 2015] Line 'example4.com' raised:
Traceback (most recent call last):
  File "/root/droopescan/dscan/plugins/internal/base_plugin_internal.py", line 362, in _process_results_multisite
    self.out.result(output, functionality)
  File "/root/droopescan/dscan/common/output.py", line 146, in result
    print(json.dumps(result))
  File "/usr/lib/python3.4/json/__init__.py", line 230, in dumps
    return _default_encoder.encode(obj)
  File "/usr/lib/python3.4/json/encoder.py", line 192, in encode
    chunks = self.iterencode(o, _one_shot=True)
  File "/usr/lib/python3.4/json/encoder.py", line 250, in iterencode
    return _iterencode(o, 0)
  File "/usr/lib/python3.4/json/encoder.py", line 173, in default
    raise TypeError(repr(o) + " is not JSON serializable")
TypeError: <MagicMock name='url_scan()' id='3057904140'> is not JSON serializable

[Tue Aug 18 20:27:55 2015] Line 'example1.com' raised:
Traceback (most recent call last):
  File "/root/droopescan/dscan/plugins/internal/base_plugin_internal.py", line 362, in _process_results_multisite
    self.out.result(output, functionality)
  File "/root/droopescan/dscan/common/output.py", line 146, in result
    print(json.dumps(result))
  File "/usr/lib/python3.4/json/__init__.py", line 230, in dumps
    return _default_encoder.encode(obj)
  File "/usr/lib/python3.4/json/encoder.py", line 192, in encode
    chunks = self.iterencode(o, _one_shot=True)
  File "/usr/lib/python3.4/json/encoder.py", line 250, in iterencode
    return _iterencode(o, 0)
  File "/usr/lib/python3.4/json/encoder.py", line 173, in default
    raise TypeError(repr(o) + " is not JSON serializable")
TypeError: <MagicMock name='url_scan()' id='3057822316'> is not JSON serializable

[Tue Aug 18 20:27:55 2015] Line 'example2.com' raised:
Traceback (most recent call last):
  File "/root/droopescan/dscan/plugins/internal/base_plugin_internal.py", line 362, in _process_results_multisite
    self.out.result(output, functionality)
  File "/root/droopescan/dscan/common/output.py", line 146, in result
    print(json.dumps(result))
  File "/usr/lib/python3.4/json/__init__.py", line 230, in dumps
    return _default_encoder.encode(obj)
  File "/usr/lib/python3.4/json/encoder.py", line 192, in encode
    chunks = self.iterencode(o, _one_shot=True)
  File "/usr/lib/python3.4/json/encoder.py", line 250, in iterencode
    return _iterencode(o, 0)
  File "/usr/lib/python3.4/json/encoder.py", line 173, in default
    raise TypeError(repr(o) + " is not JSON serializable")
TypeError: <MagicMock name='url_scan()' id='3057822316'> is not JSON serializable

[Tue Aug 18 20:27:55 2015] Line 'example3.com' raised:
Traceback (most recent call last):
  File "/root/droopescan/dscan/plugins/internal/base_plugin_internal.py", line 362, in _process_results_multisite
    self.out.result(output, functionality)
  File "/root/droopescan/dscan/common/output.py", line 146, in result
    print(json.dumps(result))
  File "/usr/lib/python3.4/json/__init__.py", line 230, in dumps
    return _default_encoder.encode(obj)
  File "/usr/lib/python3.4/json/encoder.py", line 192, in encode
    chunks = self.iterencode(o, _one_shot=True)
  File "/usr/lib/python3.4/json/encoder.py", line 250, in iterencode
    return _iterencode(o, 0)
  File "/usr/lib/python3.4/json/encoder.py", line 173, in default
    raise TypeError(repr(o) + " is not JSON serializable")
TypeError: <MagicMock name='url_scan()' id='3057822316'> is not JSON serializable

[Tue Aug 18 20:27:55 2015] Line 'example4.com' raised:
Traceback (most recent call last):
  File "/root/droopescan/dscan/plugins/internal/base_plugin_internal.py", line 362, in _process_results_multisite
    self.out.result(output, functionality)
  File "/root/droopescan/dscan/common/output.py", line 146, in result
    print(json.dumps(result))
  File "/usr/lib/python3.4/json/__init__.py", line 230, in dumps
    return _default_encoder.encode(obj)
  File "/usr/lib/python3.4/json/encoder.py", line 192, in encode
    chunks = self.iterencode(o, _one_shot=True)
  File "/usr/lib/python3.4/json/encoder.py", line 250, in iterencode
    return _iterencode(o, 0)
  File "/usr/lib/python3.4/json/encoder.py", line 173, in default
    raise TypeError(repr(o) + " is not JSON serializable")
TypeError: <MagicMock name='url_scan()' id='3057822316'> is not JSON serializable

